Workbook
Name Comments: #REF!
Name Comments: #REF!
Name Comments: #REF!
Name Comments: 'DISPATCH SHEET'!#REF!
Name LateComment: #REF!
Name LateComment: #REF!
Name LateComment: #REF!
Name LateComment: 'DISPATCH SHEET'!#REF!
Name LateComments: #REF!

Sheet SHORT SHEET
C1: Total Trucks: | E1: =COUNT(A4:A471) -> 0 | F1: TK Shipping Department - Short Sheet | H1: Total Cases: | K1: =SUM(H4:H471) -> 0
A2: Day/Date:
A3: TRIP # | B3: DESTINATION | C3: DISPATCH | D3: STATUS | E3: ORDER # | F3: ITEM NUMBER | G3: ITEM DESCRIPTION | H3: CASES | I3: W | J3: PROD. ETA | K3: COMMENTS
B4: =IF(A4="","",_xlfn.XLOOKUP(A4,'DISPATCH SHEET'!B$3:B$121,'DISPATCH SHEET'!C$3:C$121,"")) | C4: =IF(ISBLANK(A4),"",_xlfn.XLOOKUP(A4,'DISPATCH SHEET'!C$3:C$121,'DISPATCH SHEET'!#REF!,""))
B5: =IF(A5="","",_xlfn.XLOOKUP(A5,'DISPATCH SHEET'!B$3:B$121,'DISPATCH SHEET'!C$3:C$121,"")) | C5: =IF(ISBLANK(A5),"",_xlfn.XLOOKUP(A5,'DISPATCH SHEET'!B$3:B$121,'DISPATCH SHEET'!#REF!,""))
B6: =IF(A6="","",_xlfn.XLOOKUP(A6,'DISPATCH SHEET'!B$3:B$121,'DISPATCH SHEET'!C$3:C$121,"")) | C6: =IF(ISBLANK(A6),"",_xlfn.XLOOKUP(A6,'DISPATCH SHEET'!B$3:B$121,'DISPATCH SHEET'!#REF!,""))
B7: =IF(A7="","",_xlfn.XLOOKUP(A7,'DISPATCH SHEET'!B$3:B$121,'DISPATCH SHEET'!C$3:C$121,"")) | C7: =IF(ISBLANK(A7),"",_xlfn.XLOOKUP(A7,'DISPATCH SHEET'!B$3:B$121,'DISPATCH SHEET'!#REF!,""))
B8: =IF(A8="","",_xlfn.XLOOKUP(A8,'DISPATCH SHEET'!B$3:B$121,'DISPATCH SHEET'!C$3:C$121,"")) | C8: =IF(ISBLANK(A8),"",_xlfn.XLOOKUP(A8,'DISPATCH SHEET'!B$3:B$121,'DISPATCH SHEET'!#REF!,""))
B9: =IF(A9="","",_xlfn.XLOOKUP(A9,'DISPATCH SHEET'!B$3:B$121,'DISPATCH SHEET'!C$3:C$121,"")) | C9: =IF(ISBLANK(A9),"",_xlfn.XLOOKUP(A9,'DISPATCH SHEET'!B$3:B$121,'DISPATCH SHEET'!#REF!,""))
B10: =IF(A10="","",_xlfn.XLOOKUP(A10,'DISPATCH SHEET'!B$3:B$121,'DISPATCH SHEET'!C$3:C$121,"")) | C10: =IF(ISBLANK(A10),"",_xlfn.XLOOKUP(A10,'DISPATCH SHEET'!B$3:B$121,'DISPATCH SHEET'!#REF!,""))
B11: =IF(A11="","",_xlfn.XLOOKUP(A11,'DISPATCH SHEET'!B$3:B$121,'DISPATCH SHEET'!C$3:C$121,"")) | C11: =IF(ISBLANK(A11),"",_xlfn.XLOOKUP(A11,'DISPATCH SHEET'!B$3:B$121,'DISPATCH SHEET'!#REF!,""))
B12: =IF(A12="","",_xlfn.XLOOKUP(A12,'DISPATCH SHEET'!B$3:B$121,'DISPATCH SHEET'!C$3:C$121,"")) | C12: =IF(ISBLANK(A12),"",_xlfn.XLOOKUP(A12,'DISPATCH SHEET'!B$3:B$121,'DISPATCH SHEET'!#REF!,""))
B13: =IF(A13="","",_xlfn.XLOOKUP(A13,'DISPATCH SHEET'!B$3:B$121,'DISPATCH SHEET'!C$3:C$121,"")) | C13: =IF(ISBLANK(A13),"",_xlfn.XLOOKUP(A13,'DISPATCH SHEET'!B$3:B$121,'DISPATCH SHEET'!#REF!,""))
B14: =IF(A14="","",_xlfn.XLOOKUP(A14,'DISPATCH SHEET'!B$3:B$121,'DISPATCH SHEET'!C$3:C$121,"")) | C14: =IF(ISBLANK(A14),"",_xlfn.XLOOKUP(A14,'DISPATCH SHEET'!B$3:B$121,'DISPATCH SHEET'!#REF!,""))
B15: =IF(A15="","",_xlfn.XLOOKUP(A15,'DISPATCH SHEET'!B$3:B$121,'DISPATCH SHEET'!C$3:C$121,"")) | C15: =IF(ISBLANK(A15),"",_xlfn.XLOOKUP(A15,'DISPATCH SHEET'!B$3:B$121,'DISPATCH SHEET'!#REF!,""))
B16: =IF(A16="","",_xlfn.XLOOKUP(A16,'DISPATCH SHEET'!B$3:B$121,'DISPATCH SHEET'!C$3:C$121,"")) | C16: =IF(ISBLANK(A16),"",_xlfn.XLOOKUP(A16,'DISPATCH SHEET'!B$3:B$121,'DISPATCH SHEET'!#REF!,""))
... B945: =IF(A945="","",_xlfn.XLOOKUP(A945,'DISPATCH SHEET'!B$3:B$121,'DISPATCH SHEET'!C$3:C$121,"")) | C945: =IF(ISBLANK(A945),"",_xlfn.XLOOKUP(A945,'DISPATCH SHEET'!B$3:B$121,'DISPATCH SHEET'!#REF!,""))
B946: =IF(A946="","",_xlfn.XLOOKUP(A946,'DISPATCH SHEET'!B$3:B$121,'DISPATCH SHEET'!C$3:C$121,"")) | C946: =IF(ISBLANK(A946),"",_xlfn.XLOOKUP(A946,'DISPATCH SHEET'!C$3:C$121,'DISPATCH SHEET'!#REF!,""))
B947: =IF(A947="","",_xlfn.XLOOKUP(A947,'DISPATCH SHEET'!B$3:B$121,'DISPATCH SHEET'!C$3:C$121,"")) | C947: =IF(ISBLANK(A947),"",_xlfn.XLOOKUP(A947,'DISPATCH SHEET'!C$3:C$121,'DISPATCH SHEET'!#REF!,""))
B948: =IF(A948="","",_xlfn.XLOOKUP(A948,'DISPATCH SHEET'!B$3:B$121,'DISPATCH SHEET'!C$3:C$121,"")) | C948: =IF(ISBLANK(A948),"",_xlfn.XLOOKUP(A948,'DISPATCH SHEET'!C$3:C$121,'DISPATCH SHEET'!#REF!,""))
B949: =IF(A949="","",_xlfn.XLOOKUP(A949,'DISPATCH SHEET'!B$3:B$121,'DISPATCH SHEET'!C$3:C$121,"")) | C949: =IF(ISBLANK(A949),"",_xlfn.XLOOKUP(A949,'DISPATCH SHEET'!C$3:C$121,'DISPATCH SHEET'!#REF!,""))
B950: =IF(A950="","",_xlfn.XLOOKUP(A950,'DISPATCH SHEET'!B$3:B$121,'DISPATCH SHEET'!C$3:C$121,"")) | C950: =IF(ISBLANK(A950),"",_xlfn.XLOOKUP(A950,'DISPATCH SHEET'!C$3:C$121,'DISPATCH SHEET'!#REF!,""))
B951: =IF(A951="","",_xlfn.XLOOKUP(A951,'DISPATCH SHEET'!B$3:B$121,'DISPATCH SHEET'!C$3:C$121,"")) | C951: =IF(ISBLANK(A951),"",_xlfn.XLOOKUP(A951,'DISPATCH SHEET'!C$3:C$121,'DISPATCH SHEET'!#REF!,""))
B952: =IF(A952="","",_xlfn.XLOOKUP(A952,'DISPATCH SHEET'!B$3:B$121,'DISPATCH SHEET'!C$3:C$121,"")) | C952: =IF(ISBLANK(A952),"",_xlfn.XLOOKUP(A952,'DISPATCH SHEET'!C$3:C$121,'DISPATCH SHEET'!#REF!,""))
B953: =IF(A953="","",_xlfn.XLOOKUP(A953,'DISPATCH SHEET'!B$3:B$121,'DISPATCH SHEET'!C$3:C$121,"")) | C953: =IF(ISBLANK(A953),"",_xlfn.XLOOKUP(A953,'DISPATCH SHEET'!C$3:C$121,'DISPATCH SHEET'!#REF!,""))
B954: =IF(A954="","",_xlfn.XLOOKUP(A954,'DISPATCH SHEET'!B$3:B$121,'DISPATCH SHEET'!C$3:C$121,"")) | C954: =IF(ISBLANK(A954),"",_xlfn.XLOOKUP(A954,'DISPATCH SHEET'!C$3:C$121,'DISPATCH SHEET'!#REF!,""))
B955: =IF(A955="","",_xlfn.XLOOKUP(A955,'DISPATCH SHEET'!B$3:B$121,'DISPATCH SHEET'!C$3:C$121,"")) | C955: =IF(ISBLANK(A955),"",_xlfn.XLOOKUP(A955,'DISPATCH SHEET'!C$3:C$121,'DISPATCH SHEET'!#REF!,""))
B956: =IF(A956="","",_xlfn.XLOOKUP(A956,'DISPATCH SHEET'!B$3:B$121,'DISPATCH SHEET'!C$3:C$121,"")) | C956: =IF(ISBLANK(A956),"",_xlfn.XLOOKUP(A956,'DISPATCH SHEET'!C$3:C$121,'DISPATCH SHEET'!#REF!,""))
B957: =IF(A957="","",_xlfn.XLOOKUP(A957,'DISPATCH SHEET'!B$3:B$121,'DISPATCH SHEET'!C$3:C$121,"")) | C957: =IF(ISBLANK(A957),"",_xlfn.XLOOKUP(A957,'DISPATCH SHEET'!C$3:C$121,'DISPATCH SHEET'!#REF!,""))
... B3904: =IF(A3904="","",_xlfn.XLOOKUP(A3904,'DISPATCH SHEET'!B$3:B$121,'DISPATCH SHEET'!C$3:C$121,"")) | C3904: =IF(ISBLANK(A3904),"",_xlfn.XLOOKUP(A3904,'DISPATCH SHEET'!C$3:C$121,'DISPATCH SHEET'!#REF!,""))
B3905: =IF(A3905="","",_xlfn.XLOOKUP(A3905,'DISPATCH SHEET'!B$3:B$121,'DISPATCH SHEET'!C$3:C$121,""))
B3906: =IF(A3906="","",_xlfn.XLOOKUP(A3906,'DISPATCH SHEET'!B$3:B$121,'DISPATCH SHEET'!C$3:C$121,""))
B3907: =IF(A3907="","",_xlfn.XLOOKUP(A3907,'DISPATCH SHEET'!B$3:B$121,'DISPATCH SHEET'!C$3:C$121,""))
B3908: =IF(A3908="","",_xlfn.XLOOKUP(A3908,'DISPATCH SHEET'!B$3:B$121,'DISPATCH SHEET'!C$3:C$121,""))
B3909: =IF(A3909="","",_xlfn.XLOOKUP(A3909,'DISPATCH SHEET'!B$3:B$121,'DISPATCH SHEET'!C$3:C$121,""))
B3910: =IF(A3910="","",_xlfn.XLOOKUP(A3910,'DISPATCH SHEET'!B$3:B$121,'DISPATCH SHEET'!C$3:C$121,""))
B3911: =IF(A3911="","",_xlfn.XLOOKUP(A3911,'DISPATCH SHEET'!B$3:B$121,'DISPATCH SHEET'!C$3:C$121,""))
B3912: =IF(A3912="","",_xlfn.XLOOKUP(A3912,'DISPATCH SHEET'!B$3:B$121,'DISPATCH SHEET'!C$3:C$121,""))
B3913: =IF(A3913="","",_xlfn.XLOOKUP(A3913,'DISPATCH SHEET'!B$3:B$121,'DISPATCH SHEET'!C$3:C$121,""))
B3914: =IF(A3914="","",_xlfn.XLOOKUP(A3914,'DISPATCH SHEET'!B$3:B$121,'DISPATCH SHEET'!C$3:C$121,""))
...

Sheet DISPATCH SHEET
B1: Date: | E1: Daily Dispatch Log Sheet | H1: QTY: | J1: Total Weight: | K1: =COUNT(B3:B124) -> 0 | L1: Total cases: | M1: =SUM(J3:J124) -> 0
B2: LOAD# | C2: CUSTOMER | D2: CARRIER | E2: TYPE | F2: TIME | H2: TT4 | I2: WEIGHT | J2: CASES | K2: PULLS | L2: PICKS | M2: NOTES | N2: CARRIER FULL
A3: 1 | C3: #N/A | D3: #N/A | E3: =TRIM(SUBSTITUTE(D3, "trailer", "")) -> #N/A | H3: =IF(OR(ISNUMBER(SEARCH("albertson",C3)), ISNUMBER(SEARCH("jewel",C3)), ISNUMBER(SEARCH("safeway",C3)), ISNUMBER(SEARCH("sysco",C3)), ISNUMBER(SEARCH("united supermarkets",C3))),"X","") | I3: 0 | J3: 0 | K3: =IF(J3>75,ROUND((J3*0.63)/75,0),0) -> 0 | L3: =IF(J3>75,ROUND(J3*0.37,0),J3) -> 0
A4: 2 | C4: #N/A | D4: #N/A | E4: =TRIM(SUBSTITUTE(D4, "trailer", "")) -> #N/A | H4: =IF(OR(ISNUMBER(SEARCH("albertson",C4)), ISNUMBER(SEARCH("jewel",C4)), ISNUMBER(SEARCH("safeway",C4)), ISNUMBER(SEARCH("sysco",C4)), ISNUMBER(SEARCH("united supermarkets",C4))),"X","") | I4: 0 | J4: 0 | K4: =IF(J4>75,ROUND((J4*0.63)/75,0),0) -> 0 | L4: =IF(J4>75,ROUND(J4*0.37,0),J4) -> 0
A5: 3 | C5: #N/A | D5: #N/A | E5: =TRIM(SUBSTITUTE(D5, "trailer", "")) -> #N/A | H5: =IF(OR(ISNUMBER(SEARCH("albertson",C5)), ISNUMBER(SEARCH("jewel",C5)), ISNUMBER(SEARCH("safeway",C5)), ISNUMBER(SEARCH("sysco",C5)), ISNUMBER(SEARCH("united supermarkets",C5))),"X","") | I5: 0 | J5: 0 | K5: =IF(J5>75,ROUND((J5*0.63)/75,0),0) -> 0 | L5: =IF(J5>75,ROUND(J5*0.37,0),J5) -> 0
A6: 4 | C6: #N/A | D6: #N/A | E6: =TRIM(SUBSTITUTE(D6, "trailer", "")) -> #N/A | H6: =IF(OR(ISNUMBER(SEARCH("albertson",C6)), ISNUMBER(SEARCH("jewel",C6)), ISNUMBER(SEARCH("safeway",C6)), ISNUMBER(SEARCH("sysco",C6)), ISNUMBER(SEARCH("united supermarkets",C6))),"X","") | I6: 0 | J6: 0 | K6: =IF(J6>75,ROUND((J6*0.63)/75,0),0) -> 0 | L6: =IF(J6>75,ROUND(J6*0.37,0),J6) -> 0
A7: 5 | C7: #N/A | D7: #N/A | E7: =TRIM(SUBSTITUTE(D7, "trailer", "")) -> #N/A | H7: =IF(OR(ISNUMBER(SEARCH("albertson",C7)), ISNUMBER(SEARCH("jewel",C7)), ISNUMBER(SEARCH("safeway",C7)), ISNUMBER(SEARCH("sysco",C7)), ISNUMBER(SEARCH("united supermarkets",C7))),"X","") | I7: 0 | J7: 0 | K7: =IF(J7>75,ROUND((J7*0.63)/75,0),0) -> 0 | L7: =IF(J7>75,ROUND(J7*0.37,0),J7) -> 0
A8: 6 | C8: #N/A | D8: #N/A | E8: =TRIM(SUBSTITUTE(D8, "trailer", "")) -> #N/A | H8: =IF(OR(ISNUMBER(SEARCH("albertson",C8)), ISNUMBER(SEARCH("jewel",C8)), ISNUMBER(SEARCH("safeway",C8)), ISNUMBER(SEARCH("sysco",C8)), ISNUMBER(SEARCH("united supermarkets",C8))),"X","") | I8: 0 | J8: 0 | K8: =IF(J8>75,ROUND((J8*0.63)/75,0),0) -> 0 | L8: =IF(J8>75,ROUND(J8*0.37,0),J8) -> 0
A9: 7 | C9: #N/A | D9: #N/A | E9: =TRIM(SUBSTITUTE(D9, "trailer", "")) -> #N/A | H9: =IF(OR(ISNUMBER(SEARCH("albertson",C9)), ISNUMBER(SEARCH("jewel",C9)), ISNUMBER(SEARCH("safeway",C9)), ISNUMBER(SEARCH("sysco",C9)), ISNUMBER(SEARCH("united supermarkets",C9))),"X","") | I9: 0 | J9: 0 | K9: =IF(J9>75,ROUND((J9*0.63)/75,0),0) -> 0 | L9: =IF(J9>75,ROUND(J9*0.37,0),J9) -> 0
A10: 8 | C10: #N/A | D10: #N/A | E10: =TRIM(SUBSTITUTE(D10, "trailer", "")) -> #N/A | H10: =IF(OR(ISNUMBER(SEARCH("albertson",C10)), ISNUMBER(SEARCH("jewel",C10)), ISNUMBER(SEARCH("safeway",C10)), ISNUMBER(SEARCH("sysco",C10)), ISNUMBER(SEARCH("united supermarkets",C10))),"X","") | I10: 0 | J10: 0 | K10: =IF(J10>75,ROUND((J10*0.63)/75,0),0) -> 0 | L10: =IF(J10>75,ROUND(J10*0.37,0),J10) -> 0
A11: 9 | C11: #N/A | D11: #N/A | E11: =TRIM(SUBSTITUTE(D11, "trailer", "")) -> #N/A | H11: =IF(OR(ISNUMBER(SEARCH("albertson",C11)), ISNUMBER(SEARCH("jewel",C11)), ISNUMBER(SEARCH("safeway",C11)), ISNUMBER(SEARCH("sysco",C11)), ISNUMBER(SEARCH("united supermarkets",C11))),"X","") | I11: 0 | J11: 0 | K11: =IF(J11>75,ROUND((J11*0.63)/75,0),0) -> 0 | L11: =IF(J11>75,ROUND(J11*0.37,0),J11) -> 0
A12: 10 | C12: #N/A | D12: #N/A | E12: =TRIM(SUBSTITUTE(D12, "trailer", "")) -> #N/A | H12: =IF(OR(ISNUMBER(SEARCH("albertson",C12)), ISNUMBER(SEARCH("jewel",C12)), ISNUMBER(SEARCH("safeway",C12)), ISNUMBER(SEARCH("sysco",C12)), ISNUMBER(SEARCH("united supermarkets",C12))),"X","") | I12: 0 | J12: 0 | K12: =IF(J12>75,ROUND((J12*0.63)/75,0),0) -> 0 | L12: =IF(J12>75,ROUND(J12*0.37,0),J12) -> 0
A13: 12 | C13: #N/A | D13: #N/A | E13: =TRIM(SUBSTITUTE(D13, "trailer", "")) -> #N/A | H13: =IF(OR(ISNUMBER(SEARCH("albertson",C13)), ISNUMBER(SEARCH("jewel",C13)), ISNUMBER(SEARCH("safeway",C13)), ISNUMBER(SEARCH("sysco",C13)), ISNUMBER(SEARCH("united supermarkets",C13))),"X","") | I13: 0 | J13: 0 | K13: =IF(J13>75,ROUND((J13*0.63)/75,0),0) -> 0 | L13: =IF(J13>75,ROUND(J13*0.37,0),J13) -> 0
A14: 13 | C14: #N/A | D14: #N/A | E14: =TRIM(SUBSTITUTE(D14, "trailer", "")) -> #N/A | H14: =IF(OR(ISNUMBER(SEARCH("albertson",C14)), ISNUMBER(SEARCH("jewel",C14)), ISNUMBER(SEARCH("safeway",C14)), ISNUMBER(SEARCH("sysco",C14)), ISNUMBER(SEARCH("united supermarkets",C14))),"X","") | I14: 0 | J14: 0 | K14: =IF(J14>75,ROUND((J14*0.63)/75,0),0) -> 0 | L14: =IF(J14>75,ROUND(J14*0.37,0),J14) -> 0
... A93: 95 | C93: #N/A | D93: #N/A | E93: =TRIM(SUBSTITUTE(D93, "trailer", "")) -> #N/A | H93: =IF(OR(ISNUMBER(SEARCH("albertson",C93)), ISNUMBER(SEARCH("jewel",C93)), ISNUMBER(SEARCH("safeway",C93)), ISNUMBER(SEARCH("sysco",C93)), ISNUMBER(SEARCH("united supermarkets",C93))),"X","") | I93: 0 | J93: 0 | K93: =IF(J93>75,ROUND((J93*0.63)/75,0),0) -> 0 | L93: =IF(J93>75,ROUND(J93*0.37,0),J93) -> 0
A94: 96 | C94: #N/A | D94: #N/A | E94: =TRIM(SUBSTITUTE(SUBSTITUTE(D3, "drop", ""), "trailer", "")) -> #N/A | H94: =IF(OR(ISNUMBER(SEARCH("albertson",C94)), ISNUMBER(SEARCH("jewel",C94)), ISNUMBER(SEARCH("safeway",C94)), ISNUMBER(SEARCH("sysco",C94)), ISNUMBER(SEARCH("united supermarkets",C94))),"X","") | I94: 0 | J94: 0 | K94: =IF(J94>75,ROUND((J94*0.63)/75,0),0) -> 0 | L94: =IF(J94>75,ROUND(J94*0.37,0),J94) -> 0
A95: 97 | C95: #N/A | D95: #N/A | E95: =TRIM(SUBSTITUTE(SUBSTITUTE(D4, "drop", ""), "trailer", "")) -> #N/A | H95: =IF(OR(ISNUMBER(SEARCH("albertson",C95)), ISNUMBER(SEARCH("jewel",C95)), ISNUMBER(SEARCH("safeway",C95)), ISNUMBER(SEARCH("sysco",C95)), ISNUMBER(SEARCH("united supermarkets",C95))),"X","") | I95: 0 | J95: 0 | K95: =IF(J95>75,ROUND((J95*0.63)/75,0),0) -> 0 | L95: =IF(J95>75,ROUND(J95*0.37,0),J95) -> 0
A96: 98 | C96: #N/A | D96: #N/A | E96: =TRIM(SUBSTITUTE(SUBSTITUTE(D5, "drop", ""), "trailer", "")) -> #N/A | H96: =IF(OR(ISNUMBER(SEARCH("albertson",C96)), ISNUMBER(SEARCH("jewel",C96)), ISNUMBER(SEARCH("safeway",C96)), ISNUMBER(SEARCH("sysco",C96)), ISNUMBER(SEARCH("united supermarkets",C96))),"X","") | I96: 0 | J96: 0 | K96: =IF(J96>75,ROUND((J96*0.63)/75,0),0) -> 0 | L96: =IF(J96>75,ROUND(J96*0.37,0),J96) -> 0
A97: 99 | C97: #N/A | D97: #N/A | E97: =TRIM(SUBSTITUTE(SUBSTITUTE(D6, "drop", ""), "trailer", "")) -> #N/A | H97: =IF(OR(ISNUMBER(SEARCH("albertson",C97)), ISNUMBER(SEARCH("jewel",C97)), ISNUMBER(SEARCH("safeway",C97)), ISNUMBER(SEARCH("sysco",C97)), ISNUMBER(SEARCH("united supermarkets",C97))),"X","") | I97: 0 | J97: 0 | K97: =IF(J97>75,ROUND((J97*0.63)/75,0),0) -> 0 | L97: =IF(J97>75,ROUND(J97*0.37,0),J97) -> 0
A98: 100 | C98: #N/A | D98: #N/A | E98: =TRIM(SUBSTITUTE(SUBSTITUTE(D7, "drop", ""), "trailer", "")) -> #N/A | H98: =IF(OR(ISNUMBER(SEARCH("albertson",C98)), ISNUMBER(SEARCH("jewel",C98)), ISNUMBER(SEARCH("safeway",C98)), ISNUMBER(SEARCH("sysco",C98)), ISNUMBER(SEARCH("united supermarkets",C98))),"X","") | I98: 0 | J98: 0 | K98: =IF(J98>75,ROUND((J98*0.63)/75,0),0) -> 0 | L98: =IF(J98>75,ROUND(J98*0.37,0),J98) -> 0
A99: 101 | C99: #N/A | D99: #N/A | E99: =TRIM(SUBSTITUTE(SUBSTITUTE(D8, "drop", ""), "trailer", "")) -> #N/A | H99: =IF(OR(ISNUMBER(SEARCH("albertson",C99)), ISNUMBER(SEARCH("jewel",C99)), ISNUMBER(SEARCH("safeway",C99)), ISNUMBER(SEARCH("sysco",C99)), ISNUMBER(SEARCH("united supermarkets",C99))),"X","") | I99: 0 | J99: 0 | K99: =IF(J99>75,ROUND((J99*0.63)/75,0),0) -> 0 | L99: =IF(J99>75,ROUND(J99*0.37,0),J99) -> 0
A100: 102 | C100: #N/A | D100: #N/A | E100: =TRIM(SUBSTITUTE(SUBSTITUTE(D9, "drop", ""), "trailer", "")) -> #N/A | H100: =IF(OR(ISNUMBER(SEARCH("albertson",C100)), ISNUMBER(SEARCH("jewel",C100)), ISNUMBER(SEARCH("safeway",C100)), ISNUMBER(SEARCH("sysco",C100)), ISNUMBER(SEARCH("united supermarkets",C100))),"X","") | I100: 0 | J100: 0 | K100: =IF(J100>75,ROUND((J100*0.63)/75,0),0) -> 0 | L100: =IF(J100>75,ROUND(J100*0.37,0),J100) -> 0
A101: 103 | C101: #N/A | D101: #N/A | E101: =TRIM(SUBSTITUTE(SUBSTITUTE(D10, "drop", ""), "trailer", "")) -> #N/A | H101: =IF(OR(ISNUMBER(SEARCH("albertson",C101)), ISNUMBER(SEARCH("jewel",C101)), ISNUMBER(SEARCH("safeway",C101)), ISNUMBER(SEARCH("sysco",C101)), ISNUMBER(SEARCH("united supermarkets",C101))),"X","") | I101: 0 | J101: 0 | K101: =IF(J101>75,ROUND((J101*0.63)/75,0),0) -> 0 | L101: =IF(J101>75,ROUND(J101*0.37,0),J101) -> 0
A102: 104 | C102: #N/A | D102: #N/A | E102: =TRIM(SUBSTITUTE(SUBSTITUTE(D11, "drop", ""), "trailer", "")) -> #N/A | H102: =IF(OR(ISNUMBER(SEARCH("albertson",C102)), ISNUMBER(SEARCH("jewel",C102)), ISNUMBER(SEARCH("safeway",C102)), ISNUMBER(SEARCH("sysco",C102)), ISNUMBER(SEARCH("united supermarkets",C102))),"X","") | I102: 0 | J102: 0 | K102: =IF(J102>75,ROUND((J102*0.63)/75,0),0) -> 0 | L102: =IF(J102>75,ROUND(J102*0.37,0),J102) -> 0
A103: 105 | C103: #N/A | D103: #N/A | E103: =TRIM(SUBSTITUTE(SUBSTITUTE(D12, "drop", ""), "trailer", "")) -> #N/A | H103: =IF(OR(ISNUMBER(SEARCH("albertson",C103)), ISNUMBER(SEARCH("jewel",C103)), ISNUMBER(SEARCH("safeway",C103)), ISNUMBER(SEARCH("sysco",C103)), ISNUMBER(SEARCH("united supermarkets",C103))),"X","") | I103: 0 | J103: 0 | K103: =IF(J103>75,ROUND((J103*0.63)/75,0),0) -> 0 | L103: =IF(J103>75,ROUND(J103*0.37,0),J103) -> 0
A104: 106 | C104: #N/A | D104: #N/A | E104: =TRIM(SUBSTITUTE(SUBSTITUTE(D13, "drop", ""), "trailer", "")) -> #N/A | H104: =IF(OR(ISNUMBER(SEARCH("albertson",C104)), ISNUMBER(SEARCH("jewel",C104)), ISNUMBER(SEARCH("safeway",C104)), ISNUMBER(SEARCH("sysco",C104)), ISNUMBER(SEARCH("united supermarkets",C104))),"X","") | I104: 0 | J104: 0 | K104: =IF(J104>75,ROUND((J104*0.63)/75,0),0) -> 0 | L104: =IF(J104>75,ROUND(J104*0.37,0),J104) -> 0
A105: 107 | C105: #N/A | D105: #N/A | E105: =TRIM(SUBSTITUTE(SUBSTITUTE(D14, "drop", ""), "trailer", "")) -> #N/A | H105: =IF(OR(ISNUMBER(SEARCH("albertson",C105)), ISNUMBER(SEARCH("jewel",C105)), ISNUMBER(SEARCH("safeway",C105)), ISNUMBER(SEARCH("sysco",C105)), ISNUMBER(SEARCH("united supermarkets",C105))),"X","") | I105: 0 | J105: 0 | K105: =IF(J105>75,ROUND((J105*0.63)/75,0),0) -> 0 | L105: =IF(J105>75,ROUND(J105*0.37,0),J105) -> 0
... A123: 125 | C123: #N/A | D123: #N/A | E123: =TRIM(SUBSTITUTE(SUBSTITUTE(D32, "drop", ""), "trailer", "")) -> #N/A | H123: =IF(OR(ISNUMBER(SEARCH("albertson",C123)), ISNUMBER(SEARCH("jewel",C123)), ISNUMBER(SEARCH("safeway",C123)), ISNUMBER(SEARCH("sysco",C123)), ISNUMBER(SEARCH("united supermarkets",C123))),"X","") | I123: 0 | J123: 0 | K123: =IF(J123>75,ROUND((J123*0.63)/75,0),0) -> 0 | L123: =IF(J123>75,ROUND(J123*0.37,0),J123) -> 0

Sheet OPENDOCK
A1: Load Reference | B1: Arrival Date | C1: Arrival Time | D1: Departure Date | E1: Departure Time | F1: Status | G1: Carrier

Sheet CARRIERS
A1: Carrier Full Name | B1: Carrier Abbreviation
A2: ABCO TRANSPORTATION | B2: ABCO
A3: ASSOCIATED WHOLESALE GROCERS | B3: CPU
A4: AWG | B4: CPU
A5: Barlow Truck lines | B5: BARLOW
A6: BARLOW TRUCK LINES INC | B6: BARLOW
A7: BESTMARK EXPRESS | B7: BESTMARK
A8: BESTMARK EXPRESS, INC. | B8: BESTMARK
A9: BLACKWELL CONSOLIDATION | B9: BLACKWELL
A10: BOTTOMLEY ENTERPRISES | B10: BOTTOMLEY
A11: BOTTOMLEY ENTERPRISES INC | B11: BOTTOMLEY
A12: CARGO RUNNER CO | B12: CARGO RUNNER
... A118: WELLINGTON MOTOR FREIGHT | B118: WELLINGTON

Sheet MG REPORT
A1: Load # | B1: Actual Weight | C1: Actual Quantity | D1: Consignee Name
